Workbook

Sheet Orçamento
E2: Controle de Orçamento | M2: Seu nome
B6: Programação do Orçamento | I6: Distribuição do Orçamento
D9: Renda Prevista (Mensal) | E9: 3000
D10: Dívidas (Mensal)
D11: Renda Real (Mensal) | E11: =E9-E10 -> 3000
D14: Tipo de fluxo | E14: %
D15: Necessidades Básicas | E15: 0.5
D16: Lazer | E16: 0.2
D17: Educação | E17: 0.1
D18: Longo Prazo | E18: 0.1
D19: Liberdade financeira | E19: 0.1
D20: Reserva de Emergência | E20: 0
E21: =SUM(E15:E20) -> 1

Sheet Fluxo de Caixa
B2: Receitas | H2: Despesas Essenciais | N2: Lazer | T2: Investimentos
B3: Data | C3: Categoria | D3: Mês | E3: Descrição | F3: Valor | H3: Data | I3: Categoria | J3: Mês | K3: Descrição | L3: Valor | N3: Data | O3: Categoria | P3: Mês | Q3: Descrição | R3: Valor | T3: Data | U3: Categoria | V3: Mês | W3: Descrição | X3: Valor
B4: 45288 | C4: Salário | D4: =MONTH(B4) -> 12 | E4: Salário | F4: 3000 | H4: 45288 | I4: Condomínio | J4: =MONTH(H4) -> 12 | K4: Condominio 01/2024 | L4: 452.03 | N4: 45306 | O4: Assinaturas Mensais | P4: =MONTH(N4) -> 1 | Q4: Amazon Prime | R4: 15 | T4: 45289 | U4: Educação (3) | V4: =MONTH(T4) -> 12 | W4: Curso | X4: 200
B5: 45288 | C5: Vale refeição | D5: =MONTH(B5) -> 12 | F5: 1000 | J5: =MONTH(H5) -> 1 | P5: =MONTH(N5) -> 1 | V5: =MONTH(T5) -> 1
B6: 45288 | C6: Outros | D6: =MONTH(B6) -> 12 | F6: 2000 | J6: =MONTH(H6) -> 1

Sheet Acompanhamento
D2: Controle de Orçamento | M2: =Orçamento!M2 -> Seu nome
H6: Acompanhamento Mensal
B7: Mês | C7: Dezembro
B9: Tipo de fluxo | C9: Planejado | D9: Gasto atual | E9: Disponível
B10: Necessidades Básicas | C10: =Orçamento!$E15*Orçamento!$E$11 -> 1500 | D10: =HLOOKUP($C$7,Anual!$D$4:$O$52,28,FALSE) -> 452.03 | E10: =C10-D10 -> 1047.97
B11: Lazer | C11: =Orçamento!$E16*Orçamento!$E$11 -> 600 | D11: =HLOOKUP($C$7,Anual!$D$4:$O$52,41,FALSE) -> 0 | E11: =C11-D11 -> 600
B12: Educação | C12: =Orçamento!$E17*Orçamento!$E$11 -> 300 | D12: =HLOOKUP($C$7,Anual!$D$4:$O$52,46,FALSE) -> 200 | E12: =C12-D12 -> 100
B13: Longo Prazo | C13: =Orçamento!$E18*Orçamento!$E$11 -> 300 | D13: =HLOOKUP($C$7,Anual!$D$4:$O$52,47,FALSE) -> 0 | E13: =C13-D13 -> 300
B14: Liberdade financeira | C14: =Orçamento!$E19*Orçamento!$E$11 -> 300 | D14: =HLOOKUP($C$7,Anual!$D$4:$O$52,48,FALSE) -> 0 | E14: =C14-D14 -> 300
B15: Reserva de Emergência | C15: =Orçamento!$E20*Orçamento!$E$11 -> 0 | D15: =HLOOKUP($C$7,Anual!$D$4:$O$52,49,FALSE) -> 0 | E15: =C15-D15 -> 0
B16: Total | C16: =SUM(C10:C15) -> 3000 | D16: =SUM(D10:D15) -> 652.03 | E16: =C16-D16 -> 2347.97
B17: *Não edite informações dessa tabela, alterar apenas o mês em cima.

Sheet Anual
B1: Acompanhamento anual de orçamento
B3: Receitas | D3: 1 | E3: 2 | F3: 3 | G3: 4 | H3: 5 | I3: 6 | J3: 7 | K3: 8 | L3: 9 | M3: 10 | N3: 11 | O3: 12
D4: Janeiro | E4: Fevereiro | F4: Março | G4: Abril | H4: Maio | I4: Junho | J4: Julho | K4: Agosto | L4: Setembro | M4: Outubro | N4: Novembro | O4: Dezembro
B5: Renda mensal | D5: =SUMIFS('Fluxo de Caixa'!$F:$F,'Fluxo de Caixa'!$D:$D,$D$3,'Fluxo de Caixa'!$C:$C,Anual!$B$5) -> 0 | E5: =SUMIFS('Fluxo de Caixa'!$F:$F,'Fluxo de Caixa'!$D:$D,E$3,'Fluxo de Caixa'!$C:$C,Anual!$B$5) -> 0 | F5: =SUMIFS('Fluxo de Caixa'!$F:$F,'Fluxo de Caixa'!$D:$D,F$3,'Fluxo de Caixa'!$C:$C,Anual!$B$5) -> 0 | G5: =SUMIFS('Fluxo de Caixa'!$F:$F,'Fluxo de Caixa'!$D:$D,G$3,'Fluxo de Caixa'!$C:$C,Anual!$B$5) -> 0 | H5: =SUMIFS('Fluxo de Caixa'!$F:$F,'Fluxo de Caixa'!$D:$D,H$3,'Fluxo de Caixa'!$C:$C,Anual!$B$5) -> 0 | I5: =SUMIFS('Fluxo de Caixa'!$F:$F,'Fluxo de Caixa'!$D:$D,I$3,'Fluxo de Caixa'!$C:$C,Anual!$B$5) -> 0 | J5: =SUMIFS('Fluxo de Caixa'!$F:$F,'Fluxo de Caixa'!$D:$D,J$3,'Fluxo de Caixa'!$C:$C,Anual!$B$5) -> 0 | K5: =SUMIFS('Fluxo de Caixa'!$F:$F,'Fluxo de Caixa'!$D:$D,K$3,'Fluxo de Caixa'!$C:$C,Anual!$B$5) -> 0 | L5: =SUMIFS('Fluxo de Caixa'!$F:$F,'Fluxo de Caixa'!$D:$D,L$3,'Fluxo de Caixa'!$C:$C,Anual!$B$5) -> 0 | M5: =SUMIFS('Fluxo de Caixa'!$F:$F,'Fluxo de Caixa'!$D:$D,M$3,'Fluxo de Caixa'!$C:$C,Anual!$B$5) -> 0 | N5: =SUMIFS('Fluxo de Caixa'!$F:$F,'Fluxo de Caixa'!$D:$D,$N$3,'Fluxo de Caixa'!$C:$C,Anual!$B$5) -> 0 | O5: =SUMIFS('Fluxo de Caixa'!$F:$F,'Fluxo de Caixa'!$D:$D,$O$3,'Fluxo de Caixa'!$C:$C,Anual!$B$5) -> 0
B6: Vale refeição | D6: =SUMIFS('Fluxo de Caixa'!$F:$F,'Fluxo de Caixa'!$D:$D,D$3,'Fluxo de Caixa'!$C:$C,Anual!$B$6) -> 0 | E6: =SUMIFS('Fluxo de Caixa'!$F:$F,'Fluxo de Caixa'!$D:$D,E$3,'Fluxo de Caixa'!$C:$C,Anual!$B$6) -> 0 | F6: =SUMIFS('Fluxo de Caixa'!$F:$F,'Fluxo de Caixa'!$D:$D,F$3,'Fluxo de Caixa'!$C:$C,Anual!$B$6) -> 0 | G6: =SUMIFS('Fluxo de Caixa'!$F:$F,'Fluxo de Caixa'!$D:$D,G$3,'Fluxo de Caixa'!$C:$C,Anual!$B$6) -> 0 | H6: =SUMIFS('Fluxo de Caixa'!$F:$F,'Fluxo de Caixa'!$D:$D,H$3,'Fluxo de Caixa'!$C:$C,Anual!$B$6) -> 0 | I6: =SUMIFS('Fluxo de Caixa'!$F:$F,'Fluxo de Caixa'!$D:$D,I$3,'Fluxo de Caixa'!$C:$C,Anual!$B$6) -> 0 | J6: =SUMIFS('Fluxo de Caixa'!$F:$F,'Fluxo de Caixa'!$D:$D,J$3,'Fluxo de Caixa'!$C:$C,Anual!$B$6) -> 0 | K6: =SUMIFS('Fluxo de Caixa'!$F:$F,'Fluxo de Caixa'!$D:$D,K$3,'Fluxo de Caixa'!$C:$C,Anual!$B$6) -> 0 | ... O6: =SUMIFS('Fluxo de Caixa'!$F:$F,'Fluxo de Caixa'!$D:$D,O$3,'Fluxo de Caixa'!$C:$C,Anual!$B$6) -> 1000
B7: Outros | D7: =SUMIFS('Fluxo de Caixa'!$F:$F,'Fluxo de Caixa'!$D:$D,D$3,'Fluxo de Caixa'!$C:$C,Anual!$B$7) -> 0 | E7: =SUMIFS('Fluxo de Caixa'!$F:$F,'Fluxo de Caixa'!$D:$D,E$3,'Fluxo de Caixa'!$C:$C,Anual!$B$7) -> 0 | F7: =SUMIFS('Fluxo de Caixa'!$F:$F,'Fluxo de Caixa'!$D:$D,F$3,'Fluxo de Caixa'!$C:$C,Anual!$B$7) -> 0 | G7: =SUMIFS('Fluxo de Caixa'!$F:$F,'Fluxo de Caixa'!$D:$D,G$3,'Fluxo de Caixa'!$C:$C,Anual!$B$7) -> 0 | H7: =SUMIFS('Fluxo de Caixa'!$F:$F,'Fluxo de Caixa'!$D:$D,H$3,'Fluxo de Caixa'!$C:$C,Anual!$B$7) -> 0 | I7: =SUMIFS('Fluxo de Caixa'!$F:$F,'Fluxo de Caixa'!$D:$D,I$3,'Fluxo de Caixa'!$C:$C,Anual!$B$7) -> 0 | J7: =SUMIFS('Fluxo de Caixa'!$F:$F,'Fluxo de Caixa'!$D:$D,J$3,'Fluxo de Caixa'!$C:$C,Anual!$B$7) -> 0 | K7: =SUMIFS('Fluxo de Caixa'!$F:$F,'Fluxo de Caixa'!$D:$D,K$3,'Fluxo de Caixa'!$C:$C,Anual!$B$7) -> 0 | ... O7: =SUMIFS('Fluxo de Caixa'!$F:$F,'Fluxo de Caixa'!$D:$D,O$3,'Fluxo de Caixa'!$C:$C,Anual!$B$7) -> 2000
B8: Receita Total | D8: =SUM(D5:D7) -> 0 | E8: =SUM(E5:E7) -> 0 | F8: =SUM(F5:F7) -> 0 | G8: =SUM(G5:G7) -> 0 | H8: =SUM(H5:H7) -> 0 | I8: =SUM(I5:I7) -> 0 | J8: =SUM(J5:J7) -> 0 | K8: =SUM(K5:K7) -> 0 | ... O8: =SUM(O5:O7) -> 3000
B9: *Não edite informações dessa tabela. Altere apenas a planilha "Fluxo de Caixa"
B10: Despesas Essenciais (1)
B12: Condomínio | D12: =SUMIFS('Fluxo de Caixa'!$L:$L,'Fluxo de Caixa'!$J:$J,D$3,'Fluxo de Caixa'!$I:$I,Anual!$B$12) -> 0 | E12: =SUMIFS('Fluxo de Caixa'!$L:$L,'Fluxo de Caixa'!$J:$J,E$3,'Fluxo de Caixa'!$I:$I,Anual!$B$12) -> 0 | F12: =SUMIFS('Fluxo de Caixa'!$L:$L,'Fluxo de Caixa'!$J:$J,F$3,'Fluxo de Caixa'!$I:$I,Anual!$B$12) -> 0 | G12: =SUMIFS('Fluxo de Caixa'!$L:$L,'Fluxo de Caixa'!$J:$J,G$3,'Fluxo de Caixa'!$I:$I,Anual!$B$12) -> 0 | H12: =SUMIFS('Fluxo de Caixa'!$L:$L,'Fluxo de Caixa'!$J:$J,H$3,'Fluxo de Caixa'!$I:$I,Anual!$B$12) -> 0 | I12: =SUMIFS('Fluxo de Caixa'!$L:$L,'Fluxo de Caixa'!$J:$J,I$3,'Fluxo de Caixa'!$I:$I,Anual!$B$12) -> 0 | J12: =SUMIFS('Fluxo de Caixa'!$L:$L,'Fluxo de Caixa'!$J:$J,J$3,'Fluxo de Caixa'!$I:$I,Anual!$B$12) -> 0 | K12: =SUMIFS('Fluxo de Caixa'!$L:$L,'Fluxo de Caixa'!$J:$J,K$3,'Fluxo de Caixa'!$I:$I,Anual!$B$12) -> 0 | ... O12: =SUMIFS('Fluxo de Caixa'!$L:$L,'Fluxo de Caixa'!$J:$J,O$3,'Fluxo de Caixa'!$I:$I,Anual!$B$12) -> 452.03
B13: Aluguel | D13: =SUMIFS('Fluxo de Caixa'!$L:$L,'Fluxo de Caixa'!$J:$J,D$3,'Fluxo de Caixa'!$I:$I,Anual!$B$13) -> 0 | E13: =SUMIFS('Fluxo de Caixa'!$L:$L,'Fluxo de Caixa'!$J:$J,E$3,'Fluxo de Caixa'!$I:$I,Anual!$B$13) -> 0 | F13: =SUMIFS('Fluxo de Caixa'!$L:$L,'Fluxo de Caixa'!$J:$J,F$3,'Fluxo de Caixa'!$I:$I,Anual!$B$13) -> 0 | G13: =SUMIFS('Fluxo de Caixa'!$L:$L,'Fluxo de Caixa'!$J:$J,G$3,'Fluxo de Caixa'!$I:$I,Anual!$B$13) -> 0 | H13: =SUMIFS('Fluxo de Caixa'!$L:$L,'Fluxo de Caixa'!$J:$J,H$3,'Fluxo de Caixa'!$I:$I,Anual!$B$13) -> 0 | I13: =SUMIFS('Fluxo de Caixa'!$L:$L,'Fluxo de Caixa'!$J:$J,I$3,'Fluxo de Caixa'!$I:$I,Anual!$B$13) -> 0 | J13: =SUMIFS('Fluxo de Caixa'!$L:$L,'Fluxo de Caixa'!$J:$J,J$3,'Fluxo de Caixa'!$I:$I,Anual!$B$13) -> 0 | K13: =SUMIFS('Fluxo de Caixa'!$L:$L,'Fluxo de Caixa'!$J:$J,K$3,'Fluxo de Caixa'!$I:$I,Anual!$B$13) -> 0 | ... O13: =SUMIFS('Fluxo de Caixa'!$L:$L,'Fluxo de Caixa'!$J:$J,O$3,'Fluxo de Caixa'!$I:$I,Anual!$B$13) -> 0
B14: Transporte | D14: =SUMIFS('Fluxo de Caixa'!$L:$L,'Fluxo de Caixa'!$J:$J,D$3,'Fluxo de Caixa'!$I:$I,Anual!$B$14) -> 0 | E14: =SUMIFS('Fluxo de Caixa'!$L:$L,'Fluxo de Caixa'!$J:$J,E$3,'Fluxo de Caixa'!$I:$I,Anual!$B$14) -> 0 | F14: =SUMIFS('Fluxo de Caixa'!$L:$L,'Fluxo de Caixa'!$J:$J,F$3,'Fluxo de Caixa'!$I:$I,Anual!$B$14) -> 0 | G14: =SUMIFS('Fluxo de Caixa'!$L:$L,'Fluxo de Caixa'!$J:$J,G$3,'Fluxo de Caixa'!$I:$I,Anual!$B$14) -> 0 | H14: =SUMIFS('Fluxo de Caixa'!$L:$L,'Fluxo de Caixa'!$J:$J,H$3,'Fluxo de Caixa'!$I:$I,Anual!$B$14) -> 0 | I14: =SUMIFS('Fluxo de Caixa'!$L:$L,'Fluxo de Caixa'!$J:$J,I$3,'Fluxo de Caixa'!$I:$I,Anual!$B$14) -> 0 | J14: =SUMIFS('Fluxo de Caixa'!$L:$L,'Fluxo de Caixa'!$J:$J,J$3,'Fluxo de Caixa'!$I:$I,Anual!$B$14) -> 0 | K14: =SUMIFS('Fluxo de Caixa'!$L:$L,'Fluxo de Caixa'!$J:$J,K$3,'Fluxo de Caixa'!$I:$I,Anual!$B$14) -> 0 | ... O14: =SUMIFS('Fluxo de Caixa'!$L:$L,'Fluxo de Caixa'!$J:$J,O$3,'Fluxo de Caixa'!$I:$I,Anual!$B$14) -> 0
B15: Alimentação | D15: =SUMIFS('Fluxo de Caixa'!$L:$L,'Fluxo de Caixa'!$J:$J,D$3,'Fluxo de Caixa'!$I:$I,Anual!$B$15) -> 0 | E15: =SUMIFS('Fluxo de Caixa'!$L:$L,'Fluxo de Caixa'!$J:$J,E$3,'Fluxo de Caixa'!$I:$I,Anual!$B$15) -> 0 | F15: =SUMIFS('Fluxo de Caixa'!$L:$L,'Fluxo de Caixa'!$J:$J,F$3,'Fluxo de Caixa'!$I:$I,Anual!$B$15) -> 0 | G15: =SUMIFS('Fluxo de Caixa'!$L:$L,'Fluxo de Caixa'!$J:$J,G$3,'Fluxo de Caixa'!$I:$I,Anual!$B$15) -> 0 | H15: =SUMIFS('Fluxo de Caixa'!$L:$L,'Fluxo de Caixa'!$J:$J,H$3,'Fluxo de Caixa'!$I:$I,Anual!$B$15) -> 0 | I15: =SUMIFS('Fluxo de Caixa'!$L:$L,'Fluxo de Caixa'!$J:$J,I$3,'Fluxo de Caixa'!$I:$I,Anual!$B$15) -> 0 | J15: =SUMIFS('Fluxo de Caixa'!$L:$L,'Fluxo de Caixa'!$J:$J,J$3,'Fluxo de Caixa'!$I:$I,Anual!$B$15) -> 0 | K15: =SUMIFS('Fluxo de Caixa'!$L:$L,'Fluxo de Caixa'!$J:$J,K$3,'Fluxo de Caixa'!$I:$I,Anual!$B$15) -> 0 | ... O15: =SUMIFS('Fluxo de Caixa'!$L:$L,'Fluxo de Caixa'!$J:$J,O$3,'Fluxo de Caixa'!$I:$I,Anual!$B$15) -> 0
B16: Luz | D16: =SUMIFS('Fluxo de Caixa'!$L:$L,'Fluxo de Caixa'!$J:$J,D$3,'Fluxo de Caixa'!$I:$I,Anual!$B$16) -> 0 | E16: =SUMIFS('Fluxo de Caixa'!$L:$L,'Fluxo de Caixa'!$J:$J,E$3,'Fluxo de Caixa'!$I:$I,Anual!$B$16) -> 0 | F16: =SUMIFS('Fluxo de Caixa'!$L:$L,'Fluxo de Caixa'!$J:$J,F$3,'Fluxo de Caixa'!$I:$I,Anual!$B$16) -> 0 | G16: =SUMIFS('Fluxo de Caixa'!$L:$L,'Fluxo de Caixa'!$J:$J,G$3,'Fluxo de Caixa'!$I:$I,Anual!$B$16) -> 0 | H16: =SUMIFS('Fluxo de Caixa'!$L:$L,'Fluxo de Caixa'!$J:$J,H$3,'Fluxo de Caixa'!$I:$I,Anual!$B$16) -> 0 | I16: =SUMIFS('Fluxo de Caixa'!$L:$L,'Fluxo de Caixa'!$J:$J,I$3,'Fluxo de Caixa'!$I:$I,Anual!$B$16) -> 0 | J16: =SUMIFS('Fluxo de Caixa'!$L:$L,'Fluxo de Caixa'!$J:$J,J$3,'Fluxo de Caixa'!$I:$I,Anual!$B$16) -> 0 | K16: =SUMIFS('Fluxo de Caixa'!$L:$L,'Fluxo de Caixa'!$J:$J,K$3,'Fluxo de Caixa'!$I:$I,Anual!$B$16) -> 0 | ... O16: =SUMIFS('Fluxo de Caixa'!$L:$L,'Fluxo de Caixa'!$J:$J,O$3,'Fluxo de Caixa'!$I:$I,Anual!$B$16) -> 0
B17: Água | D17: =SUMIFS('Fluxo de Caixa'!$L:$L,'Fluxo de Caixa'!$J:$J,D$3,'Fluxo de Caixa'!$I:$I,Anual!$B$17) -> 0 | E17: =SUMIFS('Fluxo de Caixa'!$L:$L,'Fluxo de Caixa'!$J:$J,E$3,'Fluxo de Caixa'!$I:$I,Anual!$B$17) -> 0 | F17: =SUMIFS('Fluxo de Caixa'!$L:$L,'Fluxo de Caixa'!$J:$J,F$3,'Fluxo de Caixa'!$I:$I,Anual!$B$17) -> 0 | G17: =SUMIFS('Fluxo de Caixa'!$L:$L,'Fluxo de Caixa'!$J:$J,G$3,'Fluxo de Caixa'!$I:$I,Anual!$B$17) -> 0 | H17: =SUMIFS('Fluxo de Caixa'!$L:$L,'Fluxo de Caixa'!$J:$J,H$3,'Fluxo de Caixa'!$I:$I,Anual!$B$17) -> 0 | I17: =SUMIFS('Fluxo de Caixa'!$L:$L,'Fluxo de Caixa'!$J:$J,I$3,'Fluxo de Caixa'!$I:$I,Anual!$B$17) -> 0 | J17: =SUMIFS('Fluxo de Caixa'!$L:$L,'Fluxo de Caixa'!$J:$J,J$3,'Fluxo de Caixa'!$I:$I,Anual!$B$17) -> 0 | K17: =SUMIFS('Fluxo de Caixa'!$L:$L,'Fluxo de Caixa'!$J:$J,K$3,'Fluxo de Caixa'!$I:$I,Anual!$B$17) -> 0 | ... O17: =SUMIFS('Fluxo de Caixa'!$L:$L,'Fluxo de Caixa'!$J:$J,O$3,'Fluxo de Caixa'!$I:$I,Anual!$B$17) -> 0
B18: Internet | D18: =SUMIFS('Fluxo de Caixa'!$L:$L,'Fluxo de Caixa'!$J:$J,D$3,'Fluxo de Caixa'!$I:$I,Anual!$B$18) -> 0 | E18: =SUMIFS('Fluxo de Caixa'!$L:$L,'Fluxo de Caixa'!$J:$J,E$3,'Fluxo de Caixa'!$I:$I,Anual!$B$18) -> 0 | F18: =SUMIFS('Fluxo de Caixa'!$L:$L,'Fluxo de Caixa'!$J:$J,F$3,'Fluxo de Caixa'!$I:$I,Anual!$B$18) -> 0 | G18: =SUMIFS('Fluxo de Caixa'!$L:$L,'Fluxo de Caixa'!$J:$J,G$3,'Fluxo de Caixa'!$I:$I,Anual!$B$18) -> 0 | H18: =SUMIFS('Fluxo de Caixa'!$L:$L,'Fluxo de Caixa'!$J:$J,H$3,'Fluxo de Caixa'!$I:$I,Anual!$B$18) -> 0 | I18: =SUMIFS('Fluxo de Caixa'!$L:$L,'Fluxo de Caixa'!$J:$J,I$3,'Fluxo de Caixa'!$I:$I,Anual!$B$18) -> 0 | J18: =SUMIFS('Fluxo de Caixa'!$L:$L,'Fluxo de Caixa'!$J:$J,J$3,'Fluxo de Caixa'!$I:$I,Anual!$B$18) -> 0 | K18: =SUMIFS('Fluxo de Caixa'!$L:$L,'Fluxo de Caixa'!$J:$J,K$3,'Fluxo de Caixa'!$I:$I,Anual!$B$18) -> 0 | ... O18: =SUMIFS('Fluxo de Caixa'!$L:$L,'Fluxo de Caixa'!$J:$J,O$3,'Fluxo de Caixa'!$I:$I,Anual!$B$18) -> 0
B19: Academia | D19: =SUMIFS('Fluxo de Caixa'!$L:$L,'Fluxo de Caixa'!$J:$J,D$3,'Fluxo de Caixa'!$I:$I,Anual!$B$19) -> 0 | E19: =SUMIFS('Fluxo de Caixa'!$L:$L,'Fluxo de Caixa'!$J:$J,E$3,'Fluxo de Caixa'!$I:$I,Anual!$B$19) -> 0 | F19: =SUMIFS('Fluxo de Caixa'!$L:$L,'Fluxo de Caixa'!$J:$J,F$3,'Fluxo de Caixa'!$I:$I,Anual!$B$19) -> 0 | G19: =SUMIFS('Fluxo de Caixa'!$L:$L,'Fluxo de Caixa'!$J:$J,G$3,'Fluxo de Caixa'!$I:$I,Anual!$B$19) -> 0 | H19: =SUMIFS('Fluxo de Caixa'!$L:$L,'Fluxo de Caixa'!$J:$J,H$3,'Fluxo de Caixa'!$I:$I,Anual!$B$19) -> 0 | I19: =SUMIFS('Fluxo de Caixa'!$L:$L,'Fluxo de Caixa'!$J:$J,I$3,'Fluxo de Caixa'!$I:$I,Anual!$B$19) -> 0 | J19: =SUMIFS('Fluxo de Caixa'!$L:$L,'Fluxo de Caixa'!$J:$J,J$3,'Fluxo de Caixa'!$I:$I,Anual!$B$19) -> 0 | K19: =SUMIFS('Fluxo de Caixa'!$L:$L,'Fluxo de Caixa'!$J:$J,K$3,'Fluxo de Caixa'!$I:$I,Anual!$B$19) -> 0 | ... O19: =SUMIFS('Fluxo de Caixa'!$L:$L,'Fluxo de Caixa'!$J:$J,O$3,'Fluxo de Caixa'!$I:$I,Anual!$B$19) -> 0
B20: Saúde | D20: =SUMIFS('Fluxo de Caixa'!$L:$L,'Fluxo de Caixa'!$J:$J,D$3,'Fluxo de Caixa'!$I:$I,Anual!$B$20) -> 0 | E20: =SUMIFS('Fluxo de Caixa'!$L:$L,'Fluxo de Caixa'!$J:$J,E$3,'Fluxo de Caixa'!$I:$I,Anual!$B$20) -> 0 | F20: =SUMIFS('Fluxo de Caixa'!$L:$L,'Fluxo de Caixa'!$J:$J,F$3,'Fluxo de Caixa'!$I:$I,Anual!$B$20) -> 0 | G20: =SUMIFS('Fluxo de Caixa'!$L:$L,'Fluxo de Caixa'!$J:$J,G$3,'Fluxo de Caixa'!$I:$I,Anual!$B$20) -> 0 | H20: =SUMIFS('Fluxo de Caixa'!$L:$L,'Fluxo de Caixa'!$J:$J,H$3,'Fluxo de Caixa'!$I:$I,Anual!$B$20) -> 0 | I20: =SUMIFS('Fluxo de Caixa'!$L:$L,'Fluxo de Caixa'!$J:$J,I$3,'Fluxo de Caixa'!$I:$I,Anual!$B$20) -> 0 | J20: =SUMIFS('Fluxo de Caixa'!$L:$L,'Fluxo de Caixa'!$J:$J,J$3,'Fluxo de Caixa'!$I:$I,Anual!$B$20) -> 0 | K20: =SUMIFS('Fluxo de Caixa'!$L:$L,'Fluxo de Caixa'!$J:$J,K$3,'Fluxo de Caixa'!$I:$I,Anual!$B$20) -> 0 | ... O20: =SUMIFS('Fluxo de Caixa'!$L:$L,'Fluxo de Caixa'!$J:$J,O$3,'Fluxo de Caixa'!$I:$I,Anual!$B$20) -> 0
B21: Cartão de Crédito | D21: =SUMIFS('Fluxo de Caixa'!$L:$L,'Fluxo de Caixa'!$J:$J,D$3,'Fluxo de Caixa'!$I:$I,Anual!$B$21) -> 0 | E21: =SUMIFS('Fluxo de Caixa'!$L:$L,'Fluxo de Caixa'!$J:$J,E$3,'Fluxo de Caixa'!$I:$I,Anual!$B$21) -> 0 | F21: =SUMIFS('Fluxo de Caixa'!$L:$L,'Fluxo de Caixa'!$J:$J,F$3,'Fluxo de Caixa'!$I:$I,Anual!$B$21) -> 0 | G21: =SUMIFS('Fluxo de Caixa'!$L:$L,'Fluxo de Caixa'!$J:$J,G$3,'Fluxo de Caixa'!$I:$I,Anual!$B$21) -> 0 | H21: =SUMIFS('Fluxo de Caixa'!$L:$L,'Fluxo de Caixa'!$J:$J,H$3,'Fluxo de Caixa'!$I:$I,Anual!$B$21) -> 0 | I21: =SUMIFS('Fluxo de Caixa'!$L:$L,'Fluxo de Caixa'!$J:$J,I$3,'Fluxo de Caixa'!$I:$I,Anual!$B$21) -> 0 | J21: =SUMIFS('Fluxo de Caixa'!$L:$L,'Fluxo de Caixa'!$J:$J,J$3,'Fluxo de Caixa'!$I:$I,Anual!$B$21) -> 0 | K21: =SUMIFS('Fluxo de Caixa'!$L:$L,'Fluxo de Caixa'!$J:$J,K$3,'Fluxo de Caixa'!$I:$I,Anual!$B$21) -> 0 | ... O21: =SUMIFS('Fluxo de Caixa'!$L:$L,'Fluxo de Caixa'!$J:$J,O$3,'Fluxo de Caixa'!$I:$I,Anual!$B$21) -> 0
B22: Diarista | D22: =SUMIFS('Fluxo de Caixa'!$L:$L,'Fluxo de Caixa'!$J:$J,D$3,'Fluxo de Caixa'!$I:$I,Anual!$B$22) -> 0 | E22: =SUMIFS('Fluxo de Caixa'!$L:$L,'Fluxo de Caixa'!$J:$J,E$3,'Fluxo de Caixa'!$I:$I,Anual!$B$22) -> 0 | F22: =SUMIFS('Fluxo de Caixa'!$L:$L,'Fluxo de Caixa'!$J:$J,F$3,'Fluxo de Caixa'!$I:$I,Anual!$B$22) -> 0 | G22: =SUMIFS('Fluxo de Caixa'!$L:$L,'Fluxo de Caixa'!$J:$J,G$3,'Fluxo de Caixa'!$I:$I,Anual!$B$22) -> 0 | H22: =SUMIFS('Fluxo de Caixa'!$L:$L,'Fluxo de Caixa'!$J:$J,H$3,'Fluxo de Caixa'!$I:$I,Anual!$B$22) -> 0 | I22: =SUMIFS('Fluxo de Caixa'!$L:$L,'Fluxo de Caixa'!$J:$J,I$3,'Fluxo de Caixa'!$I:$I,Anual!$B$22) -> 0 | J22: =SUMIFS('Fluxo de Caixa'!$L:$L,'Fluxo de Caixa'!$J:$J,J$3,'Fluxo de Caixa'!$I:$I,Anual!$B$22) -> 0 | K22: =SUMIFS('Fluxo de Caixa'!$L:$L,'Fluxo de Caixa'!$J:$J,K$3,'Fluxo de Caixa'!$I:$I,Anual!$B$22) -> 0 | ... O22: =SUMIFS('Fluxo de Caixa'!$L:$L,'Fluxo de Caixa'!$J:$J,O$3,'Fluxo de Caixa'!$I:$I,Anual!$B$22) -> 0
B23: Livros | D23: =SUMIFS('Fluxo de Caixa'!$L:$L,'Fluxo de Caixa'!$J:$J,D$3,'Fluxo de Caixa'!$I:$I,Anual!$B$23) -> 0 | E23: =SUMIFS('Fluxo de Caixa'!$L:$L,'Fluxo de Caixa'!$J:$J,E$3,'Fluxo de Caixa'!$I:$I,Anual!$B$23) -> 0 | F23: =SUMIFS('Fluxo de Caixa'!$L:$L,'Fluxo de Caixa'!$J:$J,F$3,'Fluxo de Caixa'!$I:$I,Anual!$B$23) -> 0 | G23: =SUMIFS('Fluxo de Caixa'!$L:$L,'Fluxo de Caixa'!$J:$J,G$3,'Fluxo de Caixa'!$I:$I,Anual!$B$23) -> 0 | H23: =SUMIFS('Fluxo de Caixa'!$L:$L,'Fluxo de Caixa'!$J:$J,H$3,'Fluxo de Caixa'!$I:$I,Anual!$B$23) -> 0 | I23: =SUMIFS('Fluxo de Caixa'!$L:$L,'Fluxo de Caixa'!$J:$J,I$3,'Fluxo de Caixa'!$I:$I,Anual!$B$23) -> 0 | J23: =SUMIFS('Fluxo de Caixa'!$L:$L,'Fluxo de Caixa'!$J:$J,J$3,'Fluxo de Caixa'!$I:$I,Anual!$B$23) -> 0 | K23: =SUMIFS('Fluxo de Caixa'!$L:$L,'Fluxo de Caixa'!$J:$J,K$3,'Fluxo de Caixa'!$I:$I,Anual!$B$23) -> 0 | ... O23: =SUMIFS('Fluxo de Caixa'!$L:$L,'Fluxo de Caixa'!$J:$J,O$3,'Fluxo de Caixa'!$I:$I,Anual!$B$23) -> 0
B24: Empréstimo | D24: =SUMIFS('Fluxo de Caixa'!$L:$L,'Fluxo de Caixa'!$J:$J,D$3,'Fluxo de Caixa'!$I:$I,Anual!$B$24) -> 0 | E24: =SUMIFS('Fluxo de Caixa'!$L:$L,'Fluxo de Caixa'!$J:$J,E$3,'Fluxo de Caixa'!$I:$I,Anual!$B$24) -> 0 | F24: =SUMIFS('Fluxo de Caixa'!$L:$L,'Fluxo de Caixa'!$J:$J,F$3,'Fluxo de Caixa'!$I:$I,Anual!$B$24) -> 0 | G24: =SUMIFS('Fluxo de Caixa'!$L:$L,'Fluxo de Caixa'!$J:$J,G$3,'Fluxo de Caixa'!$I:$I,Anual!$B$24) -> 0 | H24: =SUMIFS('Fluxo de Caixa'!$L:$L,'Fluxo de Caixa'!$J:$J,H$3,'Fluxo de Caixa'!$I:$I,Anual!$B$24) -> 0 | I24: =SUMIFS('Fluxo de Caixa'!$L:$L,'Fluxo de Caixa'!$J:$J,I$3,'Fluxo de Caixa'!$I:$I,Anual!$B$24) -> 0 | J24: =SUMIFS('Fluxo de Caixa'!$L:$L,'Fluxo de Caixa'!$J:$J,J$3,'Fluxo de Caixa'!$I:$I,Anual!$B$24) -> 0 | K24: =SUMIFS('Fluxo de Caixa'!$L:$L,'Fluxo de Caixa'!$J:$J,K$3,'Fluxo de Caixa'!$I:$I,Anual!$B$24) -> 0 | ... O24: =SUMIFS('Fluxo de Caixa'!$L:$L,'Fluxo de Caixa'!$J:$J,O$3,'Fluxo de Caixa'!$I:$I,Anual!$B$24) -> 0
B25: Celular | D25: =SUMIFS('Fluxo de Caixa'!$L:$L,'Fluxo de Caixa'!$J:$J,D$3,'Fluxo de Caixa'!$I:$I,Anual!$B$25) -> 0 | E25: =SUMIFS('Fluxo de Caixa'!$L:$L,'Fluxo de Caixa'!$J:$J,E$3,'Fluxo de Caixa'!$I:$I,Anual!$B$25) -> 0 | F25: =SUMIFS('Fluxo de Caixa'!$L:$L,'Fluxo de Caixa'!$J:$J,F$3,'Fluxo de Caixa'!$I:$I,Anual!$B$25) -> 0 | G25: =SUMIFS('Fluxo de Caixa'!$L:$L,'Fluxo de Caixa'!$J:$J,G$3,'Fluxo de Caixa'!$I:$I,Anual!$B$25) -> 0 | H25: =SUMIFS('Fluxo de Caixa'!$L:$L,'Fluxo de Caixa'!$J:$J,H$3,'Fluxo de Caixa'!$I:$I,Anual!$B$25) -> 0 | I25: =SUMIFS('Fluxo de Caixa'!$L:$L,'Fluxo de Caixa'!$J:$J,I$3,'Fluxo de Caixa'!$I:$I,Anual!$B$25) -> 0 | J25: =SUMIFS('Fluxo de Caixa'!$L:$L,'Fluxo de Caixa'!$J:$J,J$3,'Fluxo de Caixa'!$I:$I,Anual!$B$25) -> 0 | K25: =SUMIFS('Fluxo de Caixa'!$L:$L,'Fluxo de Caixa'!$J:$J,K$3,'Fluxo de Caixa'!$I:$I,Anual!$B$25) -> 0 | ... O25: =SUMIFS('Fluxo de Caixa'!$L:$L,'Fluxo de Caixa'!$J:$J,O$3,'Fluxo de Caixa'!$I:$I,Anual!$B$25) -> 0
B26: Plano de Saúde | D26: =SUMIFS('Fluxo de Caixa'!$L:$L,'Fluxo de Caixa'!$J:$J,D$3,'Fluxo de Caixa'!$I:$I,Anual!$B$26) -> 0 | E26: =SUMIFS('Fluxo de Caixa'!$L:$L,'Fluxo de Caixa'!$J:$J,E$3,'Fluxo de Caixa'!$I:$I,Anual!$B$26) -> 0 | F26: =SUMIFS('Fluxo de Caixa'!$L:$L,'Fluxo de Caixa'!$J:$J,F$3,'Fluxo de Caixa'!$I:$I,Anual!$B$26) -> 0 | G26: =SUMIFS('Fluxo de Caixa'!$L:$L,'Fluxo de Caixa'!$J:$J,G$3,'Fluxo de Caixa'!$I:$I,Anual!$B$26) -> 0 | H26: =SUMIFS('Fluxo de Caixa'!$L:$L,'Fluxo de Caixa'!$J:$J,H$3,'Fluxo de Caixa'!$I:$I,Anual!$B$26) -> 0 | I26: =SUMIFS('Fluxo de Caixa'!$L:$L,'Fluxo de Caixa'!$J:$J,I$3,'Fluxo de Caixa'!$I:$I,Anual!$B$26) -> 0 | J26: =SUMIFS('Fluxo de Caixa'!$L:$L,'Fluxo de Caixa'!$J:$J,J$3,'Fluxo de Caixa'!$I:$I,Anual!$B$26) -> 0 | K26: =SUMIFS('Fluxo de Caixa'!$L:$L,'Fluxo de Caixa'!$J:$J,K$3,'Fluxo de Caixa'!$I:$I,Anual!$B$26) -> 0 | ... O26: =SUMIFS('Fluxo de Caixa'!$L:$L,'Fluxo de Caixa'!$J:$J,O$3,'Fluxo de Caixa'!$I:$I,Anual!$B$26) -> 0
B27: Supermercado | D27: =SUMIFS('Fluxo de Caixa'!$L:$L,'Fluxo de Caixa'!$J:$J,D$3,'Fluxo de Caixa'!$I:$I,Anual!$B$27) -> 0 | E27: =SUMIFS('Fluxo de Caixa'!$L:$L,'Fluxo de Caixa'!$J:$J,E$3,'Fluxo de Caixa'!$I:$I,Anual!$B$27) -> 0 | F27: =SUMIFS('Fluxo de Caixa'!$L:$L,'Fluxo de Caixa'!$J:$J,F$3,'Fluxo de Caixa'!$I:$I,Anual!$B$27) -> 0 | G27: =SUMIFS('Fluxo de Caixa'!$L:$L,'Fluxo de Caixa'!$J:$J,G$3,'Fluxo de Caixa'!$I:$I,Anual!$B$27) -> 0 | H27: =SUMIFS('Fluxo de Caixa'!$L:$L,'Fluxo de Caixa'!$J:$J,H$3,'Fluxo de Caixa'!$I:$I,Anual!$B$27) -> 0 | I27: =SUMIFS('Fluxo de Caixa'!$L:$L,'Fluxo de Caixa'!$J:$J,I$3,'Fluxo de Caixa'!$I:$I,Anual!$B$27) -> 0 | J27: =SUMIFS('Fluxo de Caixa'!$L:$L,'Fluxo de Caixa'!$J:$J,J$3,'Fluxo de Caixa'!$I:$I,Anual!$B$27) -> 0 | K27: =SUMIFS('Fluxo de Caixa'!$L:$L,'Fluxo de Caixa'!$J:$J,K$3,'Fluxo de Caixa'!$I:$I,Anual!$B$27) -> 0 | ... O27: =SUMIFS('Fluxo de Caixa'!$L:$L,'Fluxo de Caixa'!$J:$J,O$3,'Fluxo de Caixa'!$I:$I,Anual!$B$27) -> 0
B28: Diversos | D28: =SUMIFS('Fluxo de Caixa'!$L:$L,'Fluxo de Caixa'!$J:$J,D$3,'Fluxo de Caixa'!$I:$I,Anual!$B$28) -> 0 | E28: =SUMIFS('Fluxo de Caixa'!$L:$L,'Fluxo de Caixa'!$J:$J,E$3,'Fluxo de Caixa'!$I:$I,Anual!$B$28) -> 0 | F28: =SUMIFS('Fluxo de Caixa'!$L:$L,'Fluxo de Caixa'!$J:$J,F$3,'Fluxo de Caixa'!$I:$I,Anual!$B$28) -> 0 | G28: =SUMIFS('Fluxo de Caixa'!$L:$L,'Fluxo de Caixa'!$J:$J,G$3,'Fluxo de Caixa'!$I:$I,Anual!$B$28) -> 0 | H28: =SUMIFS('Fluxo de Caixa'!$L:$L,'Fluxo de Caixa'!$J:$J,H$3,'Fluxo de Caixa'!$I:$I,Anual!$B$28) -> 0 | I28: =SUMIFS('Fluxo de Caixa'!$L:$L,'Fluxo de Caixa'!$J:$J,I$3,'Fluxo de Caixa'!$I:$I,Anual!$B$28) -> 0 | J28: =SUMIFS('Fluxo de Caixa'!$L:$L,'Fluxo de Caixa'!$J:$J,J$3,'Fluxo de Caixa'!$I:$I,Anual!$B$28) -> 0 | K28: =SUMIFS('Fluxo de Caixa'!$L:$L,'Fluxo de Caixa'!$J:$J,K$3,'Fluxo de Caixa'!$I:$I,Anual!$B$28) -> 0 | ... O28: =SUMIFS('Fluxo de Caixa'!$L:$L,'Fluxo de Caixa'!$J:$J,O$3,'Fluxo de Caixa'!$I:$I,Anual!$B$28) -> 0
B29: Uber | D29: =SUMIFS('Fluxo de Caixa'!$L:$L,'Fluxo de Caixa'!$J:$J,D$3,'Fluxo de Caixa'!$I:$I,Anual!$B$29) -> 0 | E29: =SUMIFS('Fluxo de Caixa'!$L:$L,'Fluxo de Caixa'!$J:$J,E$3,'Fluxo de Caixa'!$I:$I,Anual!$B$29) -> 0 | F29: =SUMIFS('Fluxo de Caixa'!$L:$L,'Fluxo de Caixa'!$J:$J,F$3,'Fluxo de Caixa'!$I:$I,Anual!$B$29) -> 0 | G29: =SUMIFS('Fluxo de Caixa'!$L:$L,'Fluxo de Caixa'!$J:$J,G$3,'Fluxo de Caixa'!$I:$I,Anual!$B$29) -> 0 | H29: =SUMIFS('Fluxo de Caixa'!$L:$L,'Fluxo de Caixa'!$J:$J,H$3,'Fluxo de Caixa'!$I:$I,Anual!$B$29) -> 0 | I29: =SUMIFS('Fluxo de Caixa'!$L:$L,'Fluxo de Caixa'!$J:$J,I$3,'Fluxo de Caixa'!$I:$I,Anual!$B$29) -> 0 | J29: =SUMIFS('Fluxo de Caixa'!$L:$L,'Fluxo de Caixa'!$J:$J,J$3,'Fluxo de Caixa'!$I:$I,Anual!$B$29) -> 0 | K29: =SUMIFS('Fluxo de Caixa'!$L:$L,'Fluxo de Caixa'!$J:$J,K$3,'Fluxo de Caixa'!$I:$I,Anual!$B$29) -> 0 | ... O29: =SUMIFS('Fluxo de Caixa'!$L:$L,'Fluxo de Caixa'!$J:$J,O$3,'Fluxo de Caixa'!$I:$I,Anual!$B$29) -> 0
B30: Alterar nome do campo para personalizar #2 | D30: =SUMIFS('Fluxo de Caixa'!$L:$L,'Fluxo de Caixa'!$J:$J,D$3,'Fluxo de Caixa'!$I:$I,Anual!$B$30) -> 0 | E30: =SUMIFS('Fluxo de Caixa'!$L:$L,'Fluxo de Caixa'!$J:$J,E$3,'Fluxo de Caixa'!$I:$I,Anual!$B$30) -> 0 | F30: =SUMIFS('Fluxo de Caixa'!$L:$L,'Fluxo de Caixa'!$J:$J,F$3,'Fluxo de Caixa'!$I:$I,Anual!$B$30) -> 0 | G30: =SUMIFS('Fluxo de Caixa'!$L:$L,'Fluxo de Caixa'!$J:$J,G$3,'Fluxo de Caixa'!$I:$I,Anual!$B$30) -> 0 | H30: =SUMIFS('Fluxo de Caixa'!$L:$L,'Fluxo de Caixa'!$J:$J,H$3,'Fluxo de Caixa'!$I:$I,Anual!$B$30) -> 0 | I30: =SUMIFS('Fluxo de Caixa'!$L:$L,'Fluxo de Caixa'!$J:$J,I$3,'Fluxo de Caixa'!$I:$I,Anual!$B$30) -> 0 | J30: =SUMIFS('Fluxo de Caixa'!$L:$L,'Fluxo de Caixa'!$J:$J,J$3,'Fluxo de Caixa'!$I:$I,Anual!$B$30) -> 0 | K30: =SUMIFS('Fluxo de Caixa'!$L:$L,'Fluxo de Caixa'!$J:$J,K$3,'Fluxo de Caixa'!$I:$I,Anual!$B$30) -> 0 | ... O30: =SUMIFS('Fluxo de Caixa'!$L:$L,'Fluxo de Caixa'!$J:$J,O$3,'Fluxo de Caixa'!$I:$I,Anual!$B$30) -> 0
B31: Necessidades Básicas | D31: =SUM(D12:D30) -> 0 | E31: =SUM(E12:E30) -> 0 | F31: =SUM(F12:F30) -> 0 | G31: =SUM(G12:G30) -> 0 | H31: =SUM(H12:H30) -> 0 | I31: =SUM(I12:I30) -> 0 | J31: =SUM(J12:J30) -> 0 | K31: =SUM(K12:K30) -> 0 | ... O31: =SUM(O12:O30) -> 452.03
C32: Despesas Essenciais/Receita | D32: =D31/D8 -> #DIV/0! | E32: =E31/E8 -> #DIV/0! | G32: =G31/G8 -> #DIV/0! | H32: =H31/H8 -> #DIV/0! | I32: =I31/I8 -> #DIV/0! | J32: =J31/J8 -> #DIV/0! | K32: =K31/K8 -> #DIV/0! | L32: =L31/L8 -> #DIV/0! | M32: =M31/M8 -> #DIV/0! | N32: =N31/N8 -> #DIV/0! | O32: =O31/O8 -> 0.15067667
B33: *Não edite informações dessa tabela. Altere apenas a planilha "Fluxo de Caixa"
B34: Lazer (2)
B36: Alimentação (Gastos extras) | D36: =SUMIFS('Fluxo de Caixa'!$R:$R,'Fluxo de Caixa'!$P:$P,D$3,'Fluxo de Caixa'!$O:$O,Anual!$B$36) -> 0 | E36: =SUMIFS('Fluxo de Caixa'!$R:$R,'Fluxo de Caixa'!$P:$P,E$3,'Fluxo de Caixa'!$O:$O,Anual!$B$36) -> 0 | F36: =SUMIFS('Fluxo de Caixa'!$R:$R,'Fluxo de Caixa'!$P:$P,F$3,'Fluxo de Caixa'!$O:$O,Anual!$B$36) -> 0 | G36: =SUMIFS('Fluxo de Caixa'!$R:$R,'Fluxo de Caixa'!$P:$P,G$3,'Fluxo de Caixa'!$O:$O,Anual!$B$36) -> 0 | H36: =SUMIFS('Fluxo de Caixa'!$R:$R,'Fluxo de Caixa'!$P:$P,H$3,'Fluxo de Caixa'!$O:$O,Anual!$B$36) -> 0 | I36: =SUMIFS('Fluxo de Caixa'!$R:$R,'Fluxo de Caixa'!$P:$P,I$3,'Fluxo de Caixa'!$O:$O,Anual!$B$36) -> 0 | J36: =SUMIFS('Fluxo de Caixa'!$R:$R,'Fluxo de Caixa'!$P:$P,J$3,'Fluxo de Caixa'!$O:$O,Anual!$B$36) -> 0 | K36: =SUMIFS('Fluxo de Caixa'!$R:$R,'Fluxo de Caixa'!$P:$P,K$3,'Fluxo de Caixa'!$O:$O,Anual!$B$36) -> 0 | ... O36: =SUMIFS('Fluxo de Caixa'!$R:$R,'Fluxo de Caixa'!$P:$P,O$3,'Fluxo de Caixa'!$O:$O,Anual!$B$36) -> 0
B37: Assinaturas Mensais | D37: =SUMIFS('Fluxo de Caixa'!$R:$R,'Fluxo de Caixa'!$P:$P,D$3,'Fluxo de Caixa'!$O:$O,Anual!$B$37) -> 15 | E37: =SUMIFS('Fluxo de Caixa'!$R:$R,'Fluxo de Caixa'!$P:$P,E$3,'Fluxo de Caixa'!$O:$O,Anual!$B$37) -> 0 | F37: =SUMIFS('Fluxo de Caixa'!$R:$R,'Fluxo de Caixa'!$P:$P,F$3,'Fluxo de Caixa'!$O:$O,Anual!$B$37) -> 0 | G37: =SUMIFS('Fluxo de Caixa'!$R:$R,'Fluxo de Caixa'!$P:$P,G$3,'Fluxo de Caixa'!$O:$O,Anual!$B$37) -> 0 | H37: =SUMIFS('Fluxo de Caixa'!$R:$R,'Fluxo de Caixa'!$P:$P,H$3,'Fluxo de Caixa'!$O:$O,Anual!$B$37) -> 0 | I37: =SUMIFS('Fluxo de Caixa'!$R:$R,'Fluxo de Caixa'!$P:$P,I$3,'Fluxo de Caixa'!$O:$O,Anual!$B$37) -> 0 | J37: =SUMIFS('Fluxo de Caixa'!$R:$R,'Fluxo de Caixa'!$P:$P,J$3,'Fluxo de Caixa'!$O:$O,Anual!$B$37) -> 0 | K37: =SUMIFS('Fluxo de Caixa'!$R:$R,'Fluxo de Caixa'!$P:$P,K$3,'Fluxo de Caixa'!$O:$O,Anual!$B$37) -> 0 | ... O37: =SUMIFS('Fluxo de Caixa'!$R:$R,'Fluxo de Caixa'!$P:$P,O$3,'Fluxo de Caixa'!$O:$O,Anual!$B$37) -> 0
B38: Festas/Bares | D38: =SUMIFS('Fluxo de Caixa'!$R:$R,'Fluxo de Caixa'!$P:$P,D$3,'Fluxo de Caixa'!$O:$O,Anual!$B$38) -> 0 | E38: =SUMIFS('Fluxo de Caixa'!$R:$R,'Fluxo de Caixa'!$P:$P,E$3,'Fluxo de Caixa'!$O:$O,Anual!$B$38) -> 0 | F38: =SUMIFS('Fluxo de Caixa'!$R:$R,'Fluxo de Caixa'!$P:$P,F$3,'Fluxo de Caixa'!$O:$O,Anual!$B$38) -> 0 | G38: =SUMIFS('Fluxo de Caixa'!$R:$R,'Fluxo de Caixa'!$P:$P,G$3,'Fluxo de Caixa'!$O:$O,Anual!$B$38) -> 0 | H38: =SUMIFS('Fluxo de Caixa'!$R:$R,'Fluxo de Caixa'!$P:$P,H$3,'Fluxo de Caixa'!$O:$O,Anual!$B$38) -> 0 | I38: =SUMIFS('Fluxo de Caixa'!$R:$R,'Fluxo de Caixa'!$P:$P,I$3,'Fluxo de Caixa'!$O:$O,Anual!$B$38) -> 0 | J38: =SUMIFS('Fluxo de Caixa'!$R:$R,'Fluxo de Caixa'!$P:$P,J$3,'Fluxo de Caixa'!$O:$O,Anual!$B$38) -> 0 | K38: =SUMIFS('Fluxo de Caixa'!$R:$R,'Fluxo de Caixa'!$P:$P,K$3,'Fluxo de Caixa'!$O:$O,Anual!$B$38) -> 0 | ... O38: =SUMIFS('Fluxo de Caixa'!$R:$R,'Fluxo de Caixa'!$P:$P,O$3,'Fluxo de Caixa'!$O:$O,Anual!$B$38) -> 0
B39: Hobbies | D39: =SUMIFS('Fluxo de Caixa'!$R:$R,'Fluxo de Caixa'!$P:$P,D$3,'Fluxo de Caixa'!$O:$O,Anual!$B$39) -> 0 | E39: =SUMIFS('Fluxo de Caixa'!$R:$R,'Fluxo de Caixa'!$P:$P,E$3,'Fluxo de Caixa'!$O:$O,Anual!$B$39) -> 0 | F39: =SUMIFS('Fluxo de Caixa'!$R:$R,'Fluxo de Caixa'!$P:$P,F$3,'Fluxo de Caixa'!$O:$O,Anual!$B$39) -> 0 | G39: =SUMIFS('Fluxo de Caixa'!$R:$R,'Fluxo de Caixa'!$P:$P,G$3,'Fluxo de Caixa'!$O:$O,Anual!$B$39) -> 0 | H39: =SUMIFS('Fluxo de Caixa'!$R:$R,'Fluxo de Caixa'!$P:$P,H$3,'Fluxo de Caixa'!$O:$O,Anual!$B$39) -> 0 | I39: =SUMIFS('Fluxo de Caixa'!$R:$R,'Fluxo de Caixa'!$P:$P,I$3,'Fluxo de Caixa'!$O:$O,Anual!$B$39) -> 0 | J39: =SUMIFS('Fluxo de Caixa'!$R:$R,'Fluxo de Caixa'!$P:$P,J$3,'Fluxo de Caixa'!$O:$O,Anual!$B$39) -> 0 | K39: =SUMIFS('Fluxo de Caixa'!$R:$R,'Fluxo de Caixa'!$P:$P,K$3,'Fluxo de Caixa'!$O:$O,Anual!$B$39) -> 0 | ... O39: =SUMIFS('Fluxo de Caixa'!$R:$R,'Fluxo de Caixa'!$P:$P,O$3,'Fluxo de Caixa'!$O:$O,Anual!$B$39) -> 0
B40: Confraternização | D40: =SUMIFS('Fluxo de Caixa'!$R:$R,'Fluxo de Caixa'!$P:$P,D$3,'Fluxo de Caixa'!$O:$O,Anual!$B$40) -> 0 | E40: =SUMIFS('Fluxo de Caixa'!$R:$R,'Fluxo de Caixa'!$P:$P,E$3,'Fluxo de Caixa'!$O:$O,Anual!$B$40) -> 0 | F40: =SUMIFS('Fluxo de Caixa'!$R:$R,'Fluxo de Caixa'!$P:$P,F$3,'Fluxo de Caixa'!$O:$O,Anual!$B$40) -> 0 | G40: =SUMIFS('Fluxo de Caixa'!$R:$R,'Fluxo de Caixa'!$P:$P,G$3,'Fluxo de Caixa'!$O:$O,Anual!$B$40) -> 0 | H40: =SUMIFS('Fluxo de Caixa'!$R:$R,'Fluxo de Caixa'!$P:$P,H$3,'Fluxo de Caixa'!$O:$O,Anual!$B$40) -> 0 | I40: =SUMIFS('Fluxo de Caixa'!$R:$R,'Fluxo de Caixa'!$P:$P,I$3,'Fluxo de Caixa'!$O:$O,Anual!$B$40) -> 0 | J40: =SUMIFS('Fluxo de Caixa'!$R:$R,'Fluxo de Caixa'!$P:$P,J$3,'Fluxo de Caixa'!$O:$O,Anual!$B$40) -> 0 | K40: =SUMIFS('Fluxo de Caixa'!$R:$R,'Fluxo de Caixa'!$P:$P,K$3,'Fluxo de Caixa'!$O:$O,Anual!$B$40) -> 0 | ... O40: =SUMIFS('Fluxo de Caixa'!$R:$R,'Fluxo de Caixa'!$P:$P,O$3,'Fluxo de Caixa'!$O:$O,Anual!$B$40) -> 0
B41: Uber Lazer | D41: =SUMIFS('Fluxo de Caixa'!$R:$R,'Fluxo de Caixa'!$P:$P,D$3,'Fluxo de Caixa'!$O:$O,Anual!$B$41) -> 0 | E41: =SUMIFS('Fluxo de Caixa'!$R:$R,'Fluxo de Caixa'!$P:$P,E$3,'Fluxo de Caixa'!$O:$O,Anual!$B$41) -> 0 | F41: =SUMIFS('Fluxo de Caixa'!$R:$R,'Fluxo de Caixa'!$P:$P,F$3,'Fluxo de Caixa'!$O:$O,Anual!$B$41) -> 0 | G41: =SUMIFS('Fluxo de Caixa'!$R:$R,'Fluxo de Caixa'!$P:$P,G$3,'Fluxo de Caixa'!$O:$O,Anual!$B$41) -> 0 | H41: =SUMIFS('Fluxo de Caixa'!$R:$R,'Fluxo de Caixa'!$P:$P,H$3,'Fluxo de Caixa'!$O:$O,Anual!$B$41) -> 0 | I41: =SUMIFS('Fluxo de Caixa'!$R:$R,'Fluxo de Caixa'!$P:$P,I$3,'Fluxo de Caixa'!$O:$O,Anual!$B$41) -> 0 | J41: =SUMIFS('Fluxo de Caixa'!$R:$R,'Fluxo de Caixa'!$P:$P,J$3,'Fluxo de Caixa'!$O:$O,Anual!$B$41) -> 0 | K41: =SUMIFS('Fluxo de Caixa'!$R:$R,'Fluxo de Caixa'!$P:$P,K$3,'Fluxo de Caixa'!$O:$O,Anual!$B$41) -> 0 | ... O41: =SUMIFS('Fluxo de Caixa'!$R:$R,'Fluxo de Caixa'!$P:$P,O$3,'Fluxo de Caixa'!$O:$O,Anual!$B$41) -> 0
B42: Outros | D42: =SUMIFS('Fluxo de Caixa'!$R:$R,'Fluxo de Caixa'!$P:$P,D$3,'Fluxo de Caixa'!$O:$O,Anual!$B$42) -> 0 | E42: =SUMIFS('Fluxo de Caixa'!$R:$R,'Fluxo de Caixa'!$P:$P,E$3,'Fluxo de Caixa'!$O:$O,Anual!$B$42) -> 0 | F42: =SUMIFS('Fluxo de Caixa'!$R:$R,'Fluxo de Caixa'!$P:$P,F$3,'Fluxo de Caixa'!$O:$O,Anual!$B$42) -> 0 | G42: =SUMIFS('Fluxo de Caixa'!$R:$R,'Fluxo de Caixa'!$P:$P,G$3,'Fluxo de Caixa'!$O:$O,Anual!$B$42) -> 0 | H42: =SUMIFS('Fluxo de Caixa'!$R:$R,'Fluxo de Caixa'!$P:$P,H$3,'Fluxo de Caixa'!$O:$O,Anual!$B$42) -> 0 | I42: =SUMIFS('Fluxo de Caixa'!$R:$R,'Fluxo de Caixa'!$P:$P,I$3,'Fluxo de Caixa'!$O:$O,Anual!$B$42) -> 0 | J42: =SUMIFS('Fluxo de Caixa'!$R:$R,'Fluxo de Caixa'!$P:$P,J$3,'Fluxo de Caixa'!$O:$O,Anual!$B$42) -> 0 | K42: =SUMIFS('Fluxo de Caixa'!$R:$R,'Fluxo de Caixa'!$P:$P,K$3,'Fluxo de Caixa'!$O:$O,Anual!$B$42) -> 0 | ... O42: =SUMIFS('Fluxo de Caixa'!$R:$R,'Fluxo de Caixa'!$P:$P,O$3,'Fluxo de Caixa'!$O:$O,Anual!$B$42) -> 0
B43: Alterar nome do campo para personalizar #1 | D43: =SUMIFS('Fluxo de Caixa'!$R:$R,'Fluxo de Caixa'!$P:$P,D$3,'Fluxo de Caixa'!$O:$O,Anual!$B$43) -> 0 | E43: =SUMIFS('Fluxo de Caixa'!$R:$R,'Fluxo de Caixa'!$P:$P,E$3,'Fluxo de Caixa'!$O:$O,Anual!$B$43) -> 0 | F43: =SUMIFS('Fluxo de Caixa'!$R:$R,'Fluxo de Caixa'!$P:$P,F$3,'Fluxo de Caixa'!$O:$O,Anual!$B$43) -> 0 | G43: =SUMIFS('Fluxo de Caixa'!$R:$R,'Fluxo de Caixa'!$P:$P,G$3,'Fluxo de Caixa'!$O:$O,Anual!$B$43) -> 0 | H43: =SUMIFS('Fluxo de Caixa'!$R:$R,'Fluxo de Caixa'!$P:$P,H$3,'Fluxo de Caixa'!$O:$O,Anual!$B$43) -> 0 | I43: =SUMIFS('Fluxo de Caixa'!$R:$R,'Fluxo de Caixa'!$P:$P,I$3,'Fluxo de Caixa'!$O:$O,Anual!$B$43) -> 0 | J43: =SUMIFS('Fluxo de Caixa'!$R:$R,'Fluxo de Caixa'!$P:$P,J$3,'Fluxo de Caixa'!$O:$O,Anual!$B$43) -> 0 | K43: =SUMIFS('Fluxo de Caixa'!$R:$R,'Fluxo de Caixa'!$P:$P,K$3,'Fluxo de Caixa'!$O:$O,Anual!$B$43) -> 0 | ... O43: =SUMIFS('Fluxo de Caixa'!$R:$R,'Fluxo de Caixa'!$P:$P,O$3,'Fluxo de Caixa'!$O:$O,Anual!$B$43) -> 0
...
